Workbook

Sheet 01 PA Overview
B2: SHIFTManager • PA overview + Gantt
B3: Project Title | C3: Factory-team shift planning | PA1–PA5
B4: Project Manager | C4: Nguyễn Huy Hoàng (Team 6)
B5: Company Name | C5: HCMUS • 404NotFound | I5: PA1 | W5: PA2 | AG5: PA3 | AQ5: PA4 | BA5: PA5 | BK5: Final*
B6: Date | C6: 46314 | I6: 05 Oct | N6: 12 Oct | S6: 19 Oct | X6: 26 Oct | AC6: 02 Nov | AH6: 09 Nov | AM6: 16 Nov | AR6: 23 Nov | AW6: 30 Nov | BB6: 07 Dec | BG6: 14 Dec | BL6: 21 Dec
I7: W01 | N7: W02 | S7: W03 | X7: W04 | AC7: W05 | AH7: W06 | AM7: W07 | AR7: W08 | AW7: W09 | BB7: W10 | BG7: W11 | BL7: W12
B8: WBS ID | C8: Work package / deliverable | D8: Owner | E8: Start date | F8: Finish date | G8: Calendar days | H8: % done | I8: M | J8: T | K8: W | L8: T | M8: F | N8: M | O8: T | P8: W | Q8: T | R8: F | S8: M | T8: T | U8: W | V8: T | W8: F | X8: M | Y8: T | Z8: W | AA8: T | AB8: F | AC8: M | AD8: T | AE8: W | AF8: T | AG8: F | AH8: M | AI8: T | AJ8: W | AK8: T | AL8: F | AM8: M | AN8: T | AO8: W | AP8: T | AQ8: F | AR8: M | AS8: T | AT8: W | AU8: T | AV8: F | AW8: M | AX8: T | AY8: W | AZ8: T | BA8: F | BB8: M | BC8: T | BD8: W | BE8: T | BF8: F | BG8: M | BH8: T | BI8: W | BJ8: T | BK8: F | BL8: M | BM8: T | BN8: W | BO8: T | BP8: F
I9: 46300 | J9: 46301 | K9: 46302 | L9: 46303 | M9: 46304 | N9: 46307 | O9: 46308 | P9: 46309 | Q9: 46310 | R9: 46311 | S9: 46314 | T9: 46315 | U9: 46316 | V9: 46317 | W9: 46318 | X9: 46321 | Y9: 46322 | Z9: 46323 | AA9: 46324 | AB9: 46325 | AC9: 46328 | AD9: 46329 | AE9: 46330 | AF9: 46331 | AG9: 46332 | AH9: 46335 | AI9: 46336 | AJ9: 46337 | AK9: 46338 | AL9: 46339 | AM9: 46342 | AN9: 46343 | AO9: 46344 | AP9: 46345 | AQ9: 46346 | AR9: 46349 | AS9: 46350 | AT9: 46351 | AU9: 46352 | AV9: 46353 | AW9: 46356 | AX9: 46357 | AY9: 46358 | AZ9: 46359 | BA9: 46360 | BB9: 46363 | BC9: 46364 | BD9: 46365 | BE9: 46366 | BF9: 46367 | BG9: 46370 | BH9: 46371 | BI9: 46372 | BJ9: 46373 | BK9: 46374 | BL9: 46377 | BM9: 46378 | BN9: 46379 | BO9: 46380 | BP9: 46381
B11: 1.0 | C11: PA1 • Vision and planning | D11: Team | E11: 46309 | F11: 46315 | G11: =F11-E11+1 -> 7
B12: 1.5.1 | C12: ◆ PA1 phase gate • Submit 20 Oct | D12: Hoàng | E12: 46315 | F12: 46315 | G12: =F12-E12+1 -> 1
B13: 2.0 | C13: PA2 • Requirements + use cases | D13: Team | E13: 46316 | F13: 46328 | G13: =F13-E13+1 -> 13
B14: 2.4.1 | C14: ◆ PA2 phase gate • Submit 03 Nov | D14: Hoàng | E14: 46329 | F14: 46329 | G14: =F14-E14+1 -> 1
B15: 3.0 | C15: PA3 • Architecture and design | D15: Team | E15: 46330 | F15: 46342 | G15: =F15-E15+1 -> 13
B16: 3.5.1 | C16: ◆ PA3 phase gate • Submit 17 Nov | D16: Phúc | E16: 46343 | F16: 46343 | G16: =F16-E16+1 -> 1
B17: 4.0 | C17: PA4 • Test planning & traceability | D17: Team | E17: 46344 | F17: 46356 | G17: =F17-E17+1 -> 13
B18: 4.4.1 | C18: ◆ PA4 phase gate • Submit 01 Dec | D18: Hoàng | E18: 46357 | F18: 46357 | G18: =F18-E18+1 -> 1
B19: 5.1 | C19: PA5 • Setup and data foundation | D19: Minh / Phúc | E19: 46358 | F19: 46360 | G19: =F19-E19+1 -> 3
B20: 5.2 | C20: PA5 • Auth / scheduling / rosters | D20: Hoàng / Phúc / Minh | E20: 46360 | F20: 46367 | G20: =F20-E20+1 -> 8
B21: 5.3 | C21: PA5 • Absence and shift coverage | D21: Hoàng / Phúc | E21: 46363 | F21: 46370 | G21: =F21-E21+1 -> 8
B22: 5.4 | C22: PA5 • Test automation and review | D22: Minh / Trí | E22: 46360 | F22: 46371 | G22: =F22-E22+1 -> 12
... B25: 6.1 | C25: Final • Slides and rehearsal (tentative) | D25: Team | E25: 46372 | F25: 46374 | G25: =F25-E25+1 -> 3
B26: 6.2.1 | C26: ◆ Final presentation • Date TBD | D26: Team | G26: =F26-E26+1 -> 1
B27: 7.1 | C27: Weekly reports / meetings | D27: Team | E27: 46307 | F27: 46371 | G27: =F27-E27+1 -> 65
B28: 7.2 | C28: Project control / issue & PR review | D28: Hoàng | E28: 46310 | F28: 46371 | G28: =F28-E28+1 -> 62
G29: =F29-E29+1 -> 1
B30: READ ME | C30: All task dates are DRAFT proposals.
B31: CP | C31: ◆ Red = fixed PA gate. | G31: =F31-E31+1 -> 1
B32: NOTE | C32: Final due date TBD. | G32: =F32-E32+1 -> 1
G33: =F33-E33+1 -> 1
G34: =F34-E34+1 -> 1

Sheet 02 Detailed WBS
B1: SHIFTManager • Detailed WBS Gantt
B2: Project Title | C2: 58 WBS work packages / 351 person-hours
B3: Project Manager | C3: Nguyễn Huy Hoàng (Team 6)
B4: Company Name | C4: HCMUS • 404NotFound
B5: Date | C5: 46314 | I5: PA0 | N5: PA1 | W5: PA2 | AG5: PA3 | AQ5: PA4 | BA5: PA5 | BK5: Final*
I6: 05 Oct | N6: 12 Oct | S6: 19 Oct | X6: 26 Oct | AC6: 02 Nov | AH6: 09 Nov | AM6: 16 Nov | AR6: 23 Nov | AW6: 30 Nov | BB6: 07 Dec | BG6: 14 Dec | BL6: 21 Dec
B7: WBS ID | C7: Work package / deliverable | D7: Owner | E7: Start date | F7: Finish date | G7: Calendar days | H7: % done | I7: W01 | N7: W02 | S7: W03 | X7: W04 | AC7: W05 | AH7: W06 | AM7: W07 | AR7: W08 | AW7: W09 | BB7: W10 | BG7: W11 | BL7: W12
I8: M | J8: T | K8: W | L8: T | M8: F | N8: M | O8: T | P8: W | Q8: T | R8: F | S8: M | T8: T | U8: W | V8: T | W8: F | X8: M | Y8: T | Z8: W | AA8: T | AB8: F | AC8: M | AD8: T | AE8: W | AF8: T | AG8: F | AH8: M | AI8: T | AJ8: W | AK8: T | AL8: F | AM8: M | AN8: T | AO8: W | AP8: T | AQ8: F | AR8: M | AS8: T | AT8: W | AU8: T | AV8: F | AW8: M | AX8: T | AY8: W | AZ8: T | BA8: F | BB8: M | BC8: T | BD8: W | BE8: T | BF8: F | BG8: M | BH8: T | BI8: W | BJ8: T | BK8: F | BL8: M | BM8: T | BN8: W | BO8: T | BP8: F
I9: 46300 | J9: 46301 | K9: 46302 | L9: 46303 | M9: 46304 | N9: 46307 | O9: 46308 | P9: 46309 | Q9: 46310 | R9: 46311 | S9: 46314 | T9: 46315 | U9: 46316 | V9: 46317 | W9: 46318 | X9: 46321 | Y9: 46322 | Z9: 46323 | AA9: 46324 | AB9: 46325 | AC9: 46328 | AD9: 46329 | AE9: 46330 | AF9: 46331 | AG9: 46332 | AH9: 46335 | AI9: 46336 | AJ9: 46337 | AK9: 46338 | AL9: 46339 | AM9: 46342 | AN9: 46343 | AO9: 46344 | AP9: 46345 | AQ9: 46346 | AR9: 46349 | AS9: 46350 | AT9: 46351 | AU9: 46352 | AV9: 46353 | AW9: 46356 | AX9: 46357 | AY9: 46358 | AZ9: 46359 | BA9: 46360 | BB9: 46363 | BC9: 46364 | BD9: 46365 | BE9: 46366 | BF9: 46367 | BG9: 46370 | BH9: 46371 | BI9: 46372 | BJ9: 46373 | BK9: 46374 | BL9: 46377 | BM9: 46378 | BN9: 46379 | BO9: 46380 | BP9: 46381
B11: 1.0 | C11: PA1 • Initiation & planning
B12: 1.1.1 | C12: Preliminary Problem Statement | D12: Phúc | E12: 46309 | F12: 46310 | G12: =F12-E12+1 -> 2
B13: 1.1.2 | C13: Product Position Statement | D13: Phúc | E13: 46311 | F13: 46314 | G13: =F13-E13+1 -> 4
B14: 1.1.3 | C14: MoSCoW priorities, scope & exclusions | D14: Phúc | E14: 46311 | F14: 46314 | G14: =F14-E14+1 -> 4
B15: 1.1.4 | C15: Stakeholders and user interests | D15: Minh | E15: 46310 | F15: 46311 | G15: =F15-E15+1 -> 2
B16: 1.2.1 | C16: C4 System Context diagram | D16: Minh | E16: 46311 | F16: 46314 | G16: =F16-E16+1 -> 4
B17: 1.2.2 | C17: Technology stack and operating environment | D17: Minh | E17: 46311 | F17: 46314 | G17: =F17-E17+1 -> 4
B18: 1.3.1 | C18: Phase gates, exit criteria, roles | D18: Hoàng | E18: 46310 | F18: 46314 | G18: =F18-E18+1 -> 5
B19: 1.3.2 | C19: Three-level WBS for whole project | D19: Hoàng | E19: 46311 | F19: 46314 | G19: =F19-E19+1 -> 4
B20: 1.3.3 | C20: Estimate work-package person-hours | D20: Hoàng | E20: 46314 | F20: 46315 | G20: =F20-E20+1 -> 2
B21: 1.3.4 | C21: Gantt schedule, dependencies & critical path | D21: Trí | E21: 46314 | F21: 46315 | G21: =F21-E21+1 -> 2
B22: 1.3.5 | C22: Human resources and project cost | D22: Trí | E22: 46314 | F22: 46315 | G22: =F22-E22+1 -> 2
B23: 1.4.1 | C23: Risk register, RE, mitigation and owners | D23: Trí | E23: 46314 | F23: 46315 | G23: =F23-E23+1 -> 2
... B25: 1.5.1 | C25: ◆ Final review, contribution, AI log, export | D25: Hoàng | E25: 46315 | F25: 46315 | G25: =F25-E25+1 -> 1
B26: 2.0 | C26: PA2 • Requirements
B27: 2.1.1 | C27: Functional requirements F01–F04 (FRs) | D27: Phúc | E27: 46316 | F27: 46318 | G27: =F27-E27+1 -> 3
B28: 2.1.2 | C28: NFRs, business rules & acceptance criteria | D28: Trí | E28: 46316 | F28: 46321 | G28: =F28-E28+1 -> 6
B29: 2.2.1 | C29: Actors, Use Case diagram | D29: Phúc | E29: 46318 | F29: 46322 | G29: =F29-E29+1 -> 5
B30: 2.2.2 | C30: Use Case specifications incl exceptions | D30: Hoàng | E30: 46322 | F30: 46325 | G30: =F30-E30+1 -> 4
B31: 2.3.1 | C31: UI mockups and screen flows | D31: Minh | E31: 46317 | F31: 46324 | G31: =F31-E31+1 -> 8
B32: 2.3.2 | C32: Traceability and review issue log | D32: Trí | E32: 46325 | F32: 46328 | G32: =F32-E32+1 -> 4
B33: 2.4.1 | C33: ◆ SRS final review, contribution, AI log | D33: Hoàng | E33: 46328 | F33: 46329 | G33: =F33-E33+1 -> 2
B34: 3.0 | C34: PA3 • Design
B35: 3.1.1 | C35: C4 Container, Component, Deployment | D35: Minh | E35: 46330 | F35: 46335 | G35: =F35-E35+1 -> 6
B36: 3.1.2 | C36: At least 3 ADRs with justification | D36: Hoàng | E36: 46335 | F36: 46338 | G36: =F36-E36+1 -> 4
B37: 3.2.1 | C37: Class diagram & class specs | D37: Phúc | E37: 46331 | F37: 46336 | G37: =F37-E37+1 -> 6
B38: 3.2.2 | C38: Sequence & State diagrams | D38: Hoàng | E38: 46336 | F38: 46339 | G38: =F38-E38+1 -> 4
B39: 3.3.1 | C39: ERD and normalized schema | D39: Trí | E39: 46331 | F39: 46336 | G39: =F39-E39+1 -> 6
B40: 3.3.2 | C40: Constraints, table specs & indexes | D40: Trí | E40: 46336 | F40: 46338 | G40: =F40-E40+1 -> 3
B41: 3.4.1 | C41: Screen specs, flow, accessibility checklist | D41: Minh | E41: 46335 | F41: 46339 | G41: =F41-E41+1 -> 5
B42: 3.5.1 | C42: ◆ Design/SRS traceability review & finalize PA3 | D42: Phúc | E42: 46342 | F42: 46343 | G42: =F42-E42+1 -> 2
...

Sheet -Disclaimer-
B2: Any articles, templates, or information provided by Smartsheet on the website are for reference only. While we strive to keep the information up to date and correct, we make no representations or warranties of any kind, express or implied, about the completeness, accuracy, reliability, suitability, or availability with respect to the website or the information, articles, templates, or related graphics contained on the website. Any reliance you place on such information is therefore strictly at your own risk.

Sheet 03 Dependencies
A1: SHIFTManager | Proposed dependencies and phase-gate critical sequence
A3: Source: PA1-ProjectProposal-Plan(3).docx • WBS/effort; start/finish and predecessors are planning proposals, not approved facts.
A4: Critical = phase-gate sequence only; complete task-level CPM and resource leveling require team validation.
A6: WBS ID | B6: Work package | C6: Owner | D6: PA/Stream | E6: Effort (h) | F6: Predecessors (proposed) | G6: Start (draft) | H6: Finish (draft) | I6: Critical gate
A7: 1.1.1 | B7: Preliminary Problem Statement | C7: Phúc | D7: PA1 | E7: 3 | F7: — | G7: 46309 | H7: 46310
A8: 1.1.2 | B8: Product Position Statement | C8: Phúc | D8: PA1 | E8: 2 | F8: 1.1.1 | G8: 46311 | H8: 46314
A9: 1.1.3 | B9: MoSCoW priorities, scope & exclusions | C9: Phúc | D9: PA1 | E9: 3 | F9: 1.1.1 | G9: 46311 | H9: 46314
A10: 1.1.4 | B10: Stakeholders and user interests | C10: Minh | D10: PA1 | E10: 1.5 | F10: — | G10: 46310 | H10: 46311
A11: 1.2.1 | B11: C4 System Context diagram | C11: Minh | D11: PA1 | E11: 3 | F11: — | G11: 46311 | H11: 46314
A12: 1.2.2 | B12: Technology stack and operating environment | C12: Minh | D12: PA1 | E12: 2 | F12: — | G12: 46311 | H12: 46314
A13: 1.3.1 | B13: Phase gates, exit criteria, roles | C13: Hoàng | D13: PA1 | E13: 1.5 | F13: — | G13: 46310 | H13: 46314
A14: 1.3.2 | B14: Three-level WBS for whole project | C14: Hoàng | D14: PA1 | E14: 3.5 | F14: 1.1.1 | G14: 46311 | H14: 46314
A15: 1.3.3 | B15: Estimate work-package person-hours | C15: Hoàng | D15: PA1 | E15: 3 | F15: 1.3.2 | G15: 46314 | H15: 46315
A16: 1.3.4 | B16: Gantt schedule, dependencies & critical path | C16: Trí | D16: PA1 | E16: 4 | F16: 1.3.2, 1.3.3 | G16: 46314 | H16: 46315
A17: 1.3.5 | B17: Human resources and project cost | C17: Trí | D17: PA1 | E17: 2 | F17: 1.3.3 | G17: 46314 | H17: 46315
A18: 1.4.1 | B18: Risk register, RE, mitigation and owners | C18: Trí | D18: PA1 | E18: 4 | F18: — | G18: 46314 | H18: 46315
A19: 1.4.2 | B19: Repo, board, comms and access evidence | C19: Minh | D19: PA1 | E19: 2.5 | F19: — | G19: 46310 | H19: 46315
A20: 1.5.1 | B20: Final review, contribution, AI log, export | C20: Hoàng | D20: PA1 | E20: 2 | F20: 1.1.3, 1.2.1, 1.3.4, 1.3.5, 1.4.1, 1.4.2 | G20: 46315 | H20: 46315 | I20: YES
A21: 2.1.1 | B21: Functional requirements F01–F04 (FRs) | C21: Phúc | D21: PA2 | E21: 6 | F21: 1.5.1 | G21: 46316 | H21: 46318
A22: 2.1.2 | B22: NFRs, business rules & acceptance criteria | C22: Trí | D22: PA2 | E22: 7 | F22: — | G22: 46316 | H22: 46321
A23: 2.2.1 | B23: Actors, Use Case diagram | C23: Phúc | D23: PA2 | E23: 4 | F23: 2.1.1 | G23: 46318 | H23: 46322
A24: 2.2.2 | B24: Use Case specifications incl exceptions | C24: Hoàng | D24: PA2 | E24: 10 | F24: 2.2.1 | G24: 46322 | H24: 46325
A25: 2.3.1 | B25: UI mockups and screen flows | C25: Minh | D25: PA2 | E25: 10 | F25: 2.1.1 | G25: 46317 | H25: 46324
A26: 2.3.2 | B26: Traceability and review issue log | C26: Trí | D26: PA2 | E26: 5 | F26: 2.2.2, 2.3.1 | G26: 46325 | H26: 46328
A27: 2.4.1 | B27: SRS final review, contribution, AI log | C27: Hoàng | D27: PA2 | E27: 4 | F27: 2.1.2, 2.2.2, 2.3.2 | G27: 46328 | H27: 46329 | I27: YES
A28: 3.1.1 | B28: C4 Container, Component, Deployment | C28: Minh | D28: PA3 | E28: 7 | F28: 2.4.1 | G28: 46330 | H28: 46335
A29: 3.1.2 | B29: At least 3 ADRs with justification | C29: Hoàng | D29: PA3 | E29: 5 | F29: 3.1.1 | G29: 46335 | H29: 46338
A30: 3.2.1 | B30: Class diagram & class specs | C30: Phúc | D30: PA3 | E30: 7 | F30: 2.4.1 | G30: 46331 | H30: 46336
A31: 3.2.2 | B31: Sequence & State diagrams | C31: Hoàng | D31: PA3 | E31: 10 | F31: 3.2.1 | G31: 46336 | H31: 46339
A32: 3.3.1 | B32: ERD and normalized schema | C32: Trí | D32: PA3 | E32: 7 | F32: 2.4.1 | G32: 46331 | H32: 46336
A33: 3.3.2 | B33: Constraints, table specs & indexes | C33: Trí | D33: PA3 | E33: 5 | F33: 3.3.1 | G33: 46336 | H33: 46338
A34: 3.4.1 | B34: Screen specs, flow, accessibility checklist | C34: Minh | D34: PA3 | E34: 6 | F34: 2.3.1 | G34: 46335 | H34: 46339
A35: 3.5.1 | B35: Design/SRS traceability review & finalize PA3 | C35: Phúc | D35: PA3 | E35: 4 | F35: 3.1.2, 3.2.2, 3.3.2, 3.4.1 | G35: 46342 | H35: 46343 | I35: YES
A36: 4.1.1 | B36: Test Plan, environment, entry/exit, defect process | C36: Phúc | D36: PA4 | E36: 8 | F36: 3.5.1 | G36: 46344 | H36: 46349
A37: 4.2.1 | B37: Equivalence Partitioning and BVA design | C37: Hoàng | D37: PA4 | E37: 8 | F37: 4.1.1 | G37: 46349 | H37: 46352
A38: 4.2.2 | B38: Decision tables for scheduling and absence/coverage rules | C38: Minh | D38: PA4 | E38: 6 | F38: 4.1.1 | G38: 46349 | H38: 46352
A39: 4.3.1 | B39: Detailed test cases for F01–F04 | C39: Trí | D39: PA4 | E39: 11 | F39: 4.2.1, 4.2.2 | G39: 46351 | H39: 46356
A40: 4.3.2 | B40: Requirements–test traceability review | C40: Minh | D40: PA4 | E40: 4 | F40: 4.3.1 | G40: 46353 | H40: 46356
A41: 4.4.1 | B41: Final test plan review, contribution & AI log | C41: Hoàng | D41: PA4 | E41: 3 | F41: 4.3.1, 4.3.2 | G41: 46356 | H41: 46357 | I41: YES
A42: 5.1.1 | B42: Create React/Express project and local dev config | C42: Minh | D42: PA5 | E42: 7 | F42: 4.4.1 | G42: 46358 | H42: 46360
...

Sheet 04 Assumptions
A1: SHIFTManager | Timeline assumptions, scope and effort check
A3: Planning input | B3: Value
A4: PA1 due | B4: 46315
A5: PA2 due | B5: 46329
A6: PA3 due | B6: 46343
A7: PA4 due | B7: 46357
A8: PA5 due | B8: 46371
A9: Final presentation date | B9: TBD – do not treat draft prep as official due date
A10: Timeline shown | B10: Mon–Fri, 05 Oct – 25 Dec 2026 (12 weeks)
A11: Date validity | B11: PA deadlines supplied by the team; task dates proposed, not approved
A12: Dependency validity | B12: Predecessors are a planning draft; overlapping tasks may exchange partial drafts
A15: PA/Stream | B15: Effort (person-h) | C15: Share of total | D15: Capacity assumption | E15: Action
A16: PA1 | B16: =SUMIF('03 Dependencies'!$D$7:$D$64,A16,'03 Dependencies'!$E$7:$E$64) -> 37 | C16: =IFERROR(B16/$B$23,0) -> 0.10541311 | E16: Retrospective plan – validate actual work dates
A17: PA2 | B17: =SUMIF('03 Dependencies'!$D$7:$D$64,A17,'03 Dependencies'!$E$7:$E$64) -> 46 | C17: =IFERROR(B17/$B$23,0) -> 0.13105413 | E17: Two-week gate, proposed dates
A18: PA3 | B18: =SUMIF('03 Dependencies'!$D$7:$D$64,A18,'03 Dependencies'!$E$7:$E$64) -> 51 | C18: =IFERROR(B18/$B$23,0) -> 0.14529915 | E18: Two-week gate, proposed dates
A19: PA4 | B19: =SUMIF('03 Dependencies'!$D$7:$D$64,A19,'03 Dependencies'!$E$7:$E$64) -> 40 | C19: =IFERROR(B19/$B$23,0) -> 0.11396011 | E19: Two-week gate, proposed dates
A20: PA5 | B20: =SUMIF('03 Dependencies'!$D$7:$D$64,A20,'03 Dependencies'!$E$7:$E$64) -> 131 | C20: =IFERROR(B20/$B$23,0) -> 0.37321937 | D20: Provisional: 4 people × 16 h/week × 2 weeks = 128h | E20: 131 hours across four members in two weeks – capacity check needed
A21: Final | B21: =SUMIF('03 Dependencies'!$D$7:$D$64,A21,'03 Dependencies'!$E$7:$E$64) -> 11 | C21: =IFERROR(B21/$B$23,0) -> 0.031339031 | E21: Final due date TBD; prep dates tentative
A22: Mgmt | B22: =SUMIF('03 Dependencies'!$D$7:$D$64,A22,'03 Dependencies'!$E$7:$E$64) -> 35 | C22: =IFERROR(B22/$B$23,0) -> 0.0997151 | E22: Continuous workload spread across PA1–PA5
A23: TOTAL | B23: =SUM(B16:B22) -> 351 | C23: =SUM(C16:C22) -> 1
A26: Important scope note
A27: F01 authentication/roles, F02 automatic scheduling, F03 roster acknowledgement, F04 absence/coverage.
A28: C4 initial diagram may be revised in later PAs according to TA; this Gantt uses the current four-feature scope.
A29: Planned task dates are recommendations generated for the team, not historic evidence or contractual due dates.
A30: Calendar dates exclude weekend work, but do not model public holidays, personal availability or strict resource levelling.
A31: Only phase-gate critical chain is identified; task-level critical path must be verified by Trí with dependencies and duration.
A32: Project work packages / hours from user-supplied PA1 (3).docx; official template structure from uploaded workbook.

Sheet 05 Weekly Gantt
A1: SHIFTManager | 12-week project Gantt overview
A2: Scope: F01 Auth • F02 Auto schedule • F03 Roster • F04 Absence | source: PA1 (3)
A3: Draft work-package dates; official PA due dates fixed by team. Red marks phase submissions. Final due TBD.
A5: WBS | B5: Workstream / milestone | C5: Owner | D5: Start | E5: Due | F5: Duration (days) | G5: W01 | H5: W02 | I5: W03 | J5: W04 | K5: W05 | L5: W06 | M5: W07 | N5: W08 | O5: W09 | P5: W10 | Q5: W11 | R5: W12
G6: 46300 | H6: 46307 | I6: 46314 | J6: 46321 | K6: 46328 | L6: 46335 | M6: 46342 | N6: 46349 | O6: 46356 | P6: 46363 | Q6: 46370 | R6: 46377
A7: 1.0 | B7: PA1 • Vision and planning | C7: Team | D7: 46309 | E7: 46315 | F7: =E7-D7+1 -> 7
A8: 1.5.1 | B8: ◆ PA1 phase gate • Submit 20 Oct | C8: Hoàng | D8: 46315 | E8: 46315 | F8: =E8-D8+1 -> 1
A9: 2.0 | B9: PA2 • Requirements + use cases | C9: Team | D9: 46316 | E9: 46328 | F9: =E9-D9+1 -> 13
A10: 2.4.1 | B10: ◆ PA2 phase gate • Submit 03 Nov | C10: Hoàng | D10: 46329 | E10: 46329 | F10: =E10-D10+1 -> 1
A11: 3.0 | B11: PA3 • Architecture and design | C11: Team | D11: 46330 | E11: 46342 | F11: =E11-D11+1 -> 13
A12: 3.5.1 | B12: ◆ PA3 phase gate • Submit 17 Nov | C12: Phúc | D12: 46343 | E12: 46343 | F12: =E12-D12+1 -> 1
A13: 4.0 | B13: PA4 • Test planning & traceability | C13: Team | D13: 46344 | E13: 46356 | F13: =E13-D13+1 -> 13
A14: 4.4.1 | B14: ◆ PA4 phase gate • Submit 01 Dec | C14: Hoàng | D14: 46357 | E14: 46357 | F14: =E14-D14+1 -> 1
A15: 5.1 | B15: PA5 • Setup and data foundation | C15: Minh / Phúc | D15: 46358 | E15: 46360 | F15: =E15-D15+1 -> 3
A16: 5.2 | B16: PA5 • Auth / scheduling / rosters | C16: Hoàng / Phúc / Minh | D16: 46360 | E16: 46367 | F16: =E16-D16+1 -> 8
A17: 5.3 | B17: PA5 • Absence and shift coverage | C17: Hoàng / Phúc | D17: 46363 | E17: 46370 | F17: =E17-D17+1 -> 8
A18: 5.4 | B18: PA5 • Test automation and review | C18: Minh / Trí | D18: 46360 | E18: 46371 | F18: =E18-D18+1 -> 12
... A21: 6.1 | B21: Final • Slides and rehearsal (tentative) | C21: Team | D21: 46372 | E21: 46374 | F21: =E21-D21+1 -> 3
A22: 6.2.1 | B22: ◆ Final presentation • Date TBD | C22: Team
A23: 7.1 | B23: Weekly reports / meetings | C23: Team | D23: 46307 | E23: 46371 | F23: =E23-D23+1 -> 65
A24: 7.2 | B24: Project control / issue & PR review | C24: Hoàng | D24: 46310 | E24: 46371 | F24: =E24-D24+1 -> 62
A27: Critical chain (phase gates): 1.5.1 → 2.4.1 → 3.5.1 → 4.4.1 → 5.5.1 (task-level CPM pending review).
A28: * Final presentation date TBD; week-to-week resource feasibility, dependencies and task dates are still proposed.
